<?xml version="1.0"?>
<robot xmlns:xacro="http://wiki.ros.org/xacro" name="magni">

  <xacro:arg name="raspicam_mount" default="forward"/>
  <xacro:property name="raspicam_mount" value="$(arg raspicam_mount)"/>

  <xacro:arg name="sonars_installed" default="true"/>
  <xacro:property name="sonars_installed" value="$(arg sonars_installed)"/>

  <xacro:property name="wheel_r" value="0.1" />
  <xacro:property name="wheel_xpos" value="0.11" />


  <xacro:include filename="$(find magni_description)/urdf/magni.transmission.xacro" />
  <xacro:include filename="$(find magni_description)/urdf/magni.gazebo.xacro" />
  <xacro:include filename="$(find magni_description)/urdf/inertial.xacro" />


  <!-- Robot base_link -->
  <link name="base_link">
    <visual>
      <origin xyz="${-wheel_xpos} 0 ${-wheel_r+0.071}" rpy="0 0 0" />
      <geometry>
        <mesh filename="package://magni_description/meshes/magni_body.dae" />
      </geometry>
    </visual>
	<visual>
      <origin xyz="${-wheel_xpos-0.169} 0.17 ${-wheel_r+0.09}" rpy="0 0 ${pi}" />
      <geometry>
        <mesh filename="package://magni_description/meshes/caster_wheel.dae" />
      </geometry>
    </visual>
	<visual>
      <origin xyz="${-wheel_xpos-0.169} -0.17 ${-wheel_r+0.09}" rpy="0 0 ${pi}" />
      <geometry>
        <mesh filename="package://magni_description/meshes/caster_wheel.dae" />
      </geometry>
    </visual>
    <collision>
	  <origin xyz="${-wheel_xpos} 0 ${-wheel_r+0.151}" rpy="0 0 0" />
      <geometry>
        <box size="0.398 0.268 0.160"/>
      </geometry>
    </collision>
    <collision>
      <origin xyz="${-wheel_xpos-0.026} 0 ${-wheel_r+0.248}" rpy="0 0 0" />
      <geometry>
        <box size="0.375 0.268 0.034"/>
      </geometry>
    </collision>
    <collision>
      <origin xyz="${-wheel_xpos-0.169} 0.169 ${-wheel_r+0.106}" rpy="0 0 0" />
      <geometry>
        <box size="0.1 0.07 0.07"/>
      </geometry>
    </collision>
    <collision>
      <origin xyz="${-wheel_xpos-0.169} -0.169 ${-wheel_r+0.106}" rpy="0 0 0" />
      <geometry>
        <box size="0.1 0.07 0.07"/>
      </geometry>
    </collision>
    <xacro:box_inertial_with_origin  x="0.398" y="0.221" z="0.150" mass="10.0">
      <origin xyz="-0.15 0 0.03" rpy="0 0 0" />
    </xacro:box_inertial_with_origin>
  </link>

  <!-- Fixed offset from the floor to the center of the wheels -->
  <link name="base_footprint"/>
  <joint name="base_footprint_joint" type="fixed">
    <parent link="base_footprint"/>
    <child link="base_link"/>
    <origin xyz="0 0 ${wheel_r}" rpy="0 0 0"/>
  </joint>

  <!-- Macro for defining wheels -->
  <xacro:macro name="wheel" params="prefix reflect">
    <link name="${prefix}_wheel">
      <visual>
        <origin xyz="${-0.071*reflect} 0 0" rpy="0 ${(reflect-1)*pi/2} 0" />
        <geometry>
          <mesh filename="package://magni_description/meshes/front_wheel.dae" />
        </geometry>
      </visual>
      <collision>
        <origin xyz="0 0 0" rpy="0 ${pi/2} 0" />
        <geometry>
          <cylinder radius="${wheel_r}" length="0.05"/>
        </geometry>
      </collision>
      <collision>
        <origin xyz="${0.033*reflect} 0 0" rpy="0 ${pi/2} 0" />
        <geometry>
          <cylinder radius="0.064" length="0.016"/>
        </geometry>
      </collision>
      <xacro:cylinder_inertial_with_origin radius="${wheel_r}" length="0.05" mass="3.34">
        <origin xyz="0 0 0" rpy="0 ${pi/2} 0" />
      </xacro:cylinder_inertial_with_origin>
    </link>
    <joint name="${prefix}_wheel_joint" type="continuous">
      <axis xyz="1 0 0" rpy="0 0 0" />
      <parent link="base_link"/>
      <child link="${prefix}_wheel"/>
      <origin xyz="0 ${0.163*reflect} 0" rpy="0 0 ${pi/2}"/>
    </joint>
  </xacro:macro>

  <xacro:wheel prefix="left" reflect="1"/>
  <xacro:wheel prefix="right" reflect="-1"/>



  <!-- Macro for defining caster wheels -->
  <xacro:macro name="caster_wheel" params="prefix reflect">
    <link name="${prefix}_caster_wheel">
      <collision>
        <origin xyz="${-wheel_xpos-0.19} ${reflect*0.169} ${-wheel_r+0.04}" rpy="0 0 0" />
        <geometry>
          <sphere radius="0.04"/>
        </geometry>
      </collision>
    </link>
    <joint name="${prefix}_caster_wheel_joint" type="fixed">
      <parent link="base_link"/>
      <child link="${prefix}_caster_wheel"/>
    </joint>
  </xacro:macro>

  <xacro:caster_wheel prefix="left" reflect="1"/>
  <xacro:caster_wheel prefix="right" reflect="-1"/>



  <!-- Macro for defining sonars -->
  <xacro:macro name="sonar" params="name *origin">
    <link name="${name}"/>
    <joint name="${name}" type="fixed">
      <parent link="base_link"/>
      <child link="${name}"/>
      <xacro:insert_block name="origin"/>
    </joint>
  </xacro:macro>

  <!-- Define all sonars, if sonars_installed set to 1 -->
  <xacro:if value="${sonars_installed}">
    <xacro:sonar name="sonar_0">
      <origin xyz="0.01 -0.14 0.15" rpy="0 0 ${-pi/2}"/>
    </xacro:sonar>
    <xacro:sonar name="sonar_1">
      <origin xyz="0.08 -0.07 0.15" rpy="0 0 0.785"/>
    </xacro:sonar>
    <xacro:sonar name="sonar_2">
      <origin xyz="0.08 -0.01 0.15" rpy="0 0 -0.785"/>
    </xacro:sonar>
    <xacro:sonar name="sonar_3">
      <origin xyz="0.08 0.04 0.15" rpy="0 0 0"/>
    </xacro:sonar>
    <xacro:sonar name="sonar_4">
      <origin xyz="0.01 0.14 0.15" rpy="0 0 ${pi/2}"/>
    </xacro:sonar>
  </xacro:if>

  <!-- Macro for defining raspicam -->
  <xacro:macro name="raspicam" params="*origin">
    <link name="raspicam"/>
    <joint name="raspicam" type="fixed">
      <parent link="base_link"/>
      <child link="raspicam"/>
      <xacro:insert_block name="origin"/>
    </joint>
  </xacro:macro>

  <!-- Define raspicam based on the raspicam_mount argument -->
  <xacro:if value="${raspicam_mount == 'forward'}">
    <xacro:raspicam>
      <origin xyz="0.035 0.085 0.14" rpy="1.15191731 0 1.5707"/>
    </xacro:raspicam>
  </xacro:if>
  <xacro:if value="${raspicam_mount == 'upward'}">
    <xacro:raspicam>
      <origin xyz="0.035 0.15 0.14" rpy="0 0 ${pi}"/>
    </xacro:raspicam>
  </xacro:if>


</robot>
