<?xml version="1.0" ?>
<!-- =================================================================================== -->
<!-- |    This document was autogenerated by xacro from magni.urdf.xacro               | -->
<!-- |    EDITING THIS FILE BY HAND IS NOT RECOMMENDED                                 | -->
<!-- =================================================================================== -->
<robot name="magni">
  <transmission name="left_wheel_transmission">
    <type>transmission_interface/SimpleTransmission</type>
    <joint name="left_wheel_joint">
      <hardwareInterface>hardware_interface/VelocityJointInterface</hardwareInterface>
    </joint>
    <actuator name="left_wheel_actuator">
      <mechanicalReduction>1</mechanicalReduction>
      <hardwareInterface>VelocityJointInterface</hardwareInterface>
    </actuator>
  </transmission>
  <transmission name="right_wheel_transmission">
    <type>transmission_interface/SimpleTransmission</type>
    <joint name="right_wheel_joint">
      <hardwareInterface>hardware_interface/VelocityJointInterface</hardwareInterface>
    </joint>
    <actuator name="right_wheel_actuator">
      <mechanicalReduction>1</mechanicalReduction>
      <hardwareInterface>VelocityJointInterface</hardwareInterface>
    </actuator>
  </transmission>
  <gazebo>
    <plugin filename="libgazebo_ros_control.so" name="gazebo_ros_control">
      <legacyModeNS>true</legacyModeNS>
    </plugin>
  </gazebo>
  <gazebo>
    <plugin filename="libgazebo_ros_p3d.so" name="gazebo_ros_p3d">
      <updateRate>100</updateRate>
      <bodyName>base_footprint</bodyName>
      <topicName>exact_pose</topicName>
      <frameName>map</frameName>
    </plugin>
  </gazebo>
  <gazebo reference="left_wheel">
    <mu1>1.0</mu1>
    <mu2>1.0</mu2>
    <fdir1>0 0 1</fdir1>
    <minDepth>0.005</minDepth>
    <kp>1e8</kp>
  </gazebo>
  <gazebo reference="right_wheel">
    <mu1>1.0</mu1>
    <mu2>1.0</mu2>
    <fdir1>0 0 1</fdir1>
    <minDepth>0.005</minDepth>
    <kp>1e8</kp>
  </gazebo>
  <gazebo reference="left_caster_wheel">
    <mu1>0.0</mu1>
    <mu2>0.0</mu2>
    <minDepth>0.005</minDepth>
    <kp>1e8</kp>
  </gazebo>
  <gazebo reference="right_caster_wheel">
    <mu1>0.0</mu1>
    <mu2>0.0</mu2>
    <minDepth>0.005</minDepth>
    <kp>1e8</kp>
  </gazebo>
  <!-- see https://secure.wikimedia.org/wikipedia/en/wiki/List_of_moment_of_inertia_tensors -->
  <!-- Robot base_link -->
  <link name="base_link">
    <visual>
      <origin rpy="0 0 0" xyz="-0.11 0 -0.029000000000000012"/>
      <geometry>
        <mesh filename="package://magni_description/meshes/magni_body.dae"/>
      </geometry>
    </visual>
    <visual>
      <origin rpy="0 0 3.141592653589793" xyz="-0.279 0.17 -0.010000000000000009"/>
      <geometry>
        <mesh filename="package://magni_description/meshes/caster_wheel.dae"/>
      </geometry>
    </visual>
    <visual>
      <origin rpy="0 0 3.141592653589793" xyz="-0.279 -0.17 -0.010000000000000009"/>
      <geometry>
        <mesh filename="package://magni_description/meshes/caster_wheel.dae"/>
      </geometry>
    </visual>
    <collision>
      <origin rpy="0 0 0" xyz="-0.11 0 0.05099999999999999"/>
      <geometry>
        <box size="0.398 0.268 0.160"/>
      </geometry>
    </collision>
    <collision>
      <origin rpy="0 0 0" xyz="-0.136 0 0.148"/>
      <geometry>
        <box size="0.375 0.268 0.034"/>
      </geometry>
    </collision>
    <collision>
      <origin rpy="0 0 0" xyz="-0.279 0.169 0.0059999999999999915"/>
      <geometry>
        <box size="0.1 0.07 0.07"/>
      </geometry>
    </collision>
    <collision>
      <origin rpy="0 0 0" xyz="-0.279 -0.169 0.0059999999999999915"/>
      <geometry>
        <box size="0.1 0.07 0.07"/>
      </geometry>
    </collision>
    <inertial>
      <mass value="10.0"/>
      <origin rpy="0 0 0" xyz="-0.15 0 0.03"/>
      <inertia ixx="0.059450809553" ixy="0.0" ixz="0.0" iyy="0.150753273032" iyz="0.0" izz="0.17270409758500002"/>
    </inertial>
  </link>
  <!-- Fixed offset from the floor to the center of the wheels -->
  <link name="base_footprint"/>
  <joint name="base_footprint_joint" type="fixed">
    <parent link="base_footprint"/>
    <child link="base_link"/>
    <origin rpy="0 0 0" xyz="0 0 0.1"/>
  </joint>
  <link name="left_wheel">
    <visual>
      <origin rpy="0 0.0 0" xyz="-0.071 0 0"/>
      <geometry>
        <mesh filename="package://magni_description/meshes/front_wheel.dae"/>
      </geometry>
    </visual>
    <collision>
      <origin rpy="0 1.5707963267948966 0" xyz="0 0 0"/>
      <geometry>
        <cylinder length="0.05" radius="0.1"/>
      </geometry>
    </collision>
    <collision>
      <origin rpy="0 1.5707963267948966 0" xyz="0.033 0 0"/>
      <geometry>
        <cylinder length="0.016" radius="0.064"/>
      </geometry>
    </collision>
    <inertial>
      <mass value="3.34"/>
      <origin rpy="0 1.5707963267948966 0" xyz="0 0 0"/>
      <inertia ixx="0.009045829715000002" ixy="0.0" ixz="0.0" iyy="0.009045829715000002" iyz="0.0" izz="0.016700000000000003"/>
    </inertial>
  </link>
  <joint name="left_wheel_joint" type="continuous">
    <axis rpy="0 0 0" xyz="1 0 0"/>
    <parent link="base_link"/>
    <child link="left_wheel"/>
    <origin rpy="0 0 1.5707963267948966" xyz="0 0.163 0"/>
  </joint>
  <link name="right_wheel">
    <visual>
      <origin rpy="0 -3.141592653589793 0" xyz="0.071 0 0"/>
      <geometry>
        <mesh filename="package://magni_description/meshes/front_wheel.dae"/>
      </geometry>
    </visual>
    <collision>
      <origin rpy="0 1.5707963267948966 0" xyz="0 0 0"/>
      <geometry>
        <cylinder length="0.05" radius="0.1"/>
      </geometry>
    </collision>
    <collision>
      <origin rpy="0 1.5707963267948966 0" xyz="-0.033 0 0"/>
      <geometry>
        <cylinder length="0.016" radius="0.064"/>
      </geometry>
    </collision>
    <inertial>
      <mass value="3.34"/>
      <origin rpy="0 1.5707963267948966 0" xyz="0 0 0"/>
      <inertia ixx="0.009045829715000002" ixy="0.0" ixz="0.0" iyy="0.009045829715000002" iyz="0.0" izz="0.016700000000000003"/>
    </inertial>
  </link>
  <joint name="right_wheel_joint" type="continuous">
    <axis rpy="0 0 0" xyz="1 0 0"/>
    <parent link="base_link"/>
    <child link="right_wheel"/>
    <origin rpy="0 0 1.5707963267948966" xyz="0 -0.163 0"/>
  </joint>
  <link name="left_caster_wheel">
    <collision>
      <origin rpy="0 0 0" xyz="-0.3 0.169 -0.060000000000000005"/>
      <geometry>
        <sphere radius="0.04"/>
      </geometry>
    </collision>
  </link>
  <joint name="left_caster_wheel_joint" type="fixed">
    <parent link="base_link"/>
    <child link="left_caster_wheel"/>
  </joint>
  <link name="right_caster_wheel">
    <collision>
      <origin rpy="0 0 0" xyz="-0.3 -0.169 -0.060000000000000005"/>
      <geometry>
        <sphere radius="0.04"/>
      </geometry>
    </collision>
  </link>
  <joint name="right_caster_wheel_joint" type="fixed">
    <parent link="base_link"/>
    <child link="right_caster_wheel"/>
  </joint>
  <joint name="sonar_0_joint" type="fixed">
    <parent link="base_link"/>
    <child link="sonar_0"/>
    <origin rpy="0 0 -1.5707963267948966" xyz="0.01 -0.14 0.15"/>
  </joint>
  <link name="sonar_0">
    <visual>
      <origin rpy="1.5707963267948966 0 1.5707963267948966" xyz="-0.006 0 0"/>
      <geometry>
        <mesh filename="package://magni_description/meshes/sensors/sonar_hc-sr04.dae"/>
      </geometry>
    </visual>
    <!-- removing colisions from sonars solves issue https://github.com/UbiquityRobotics/magni_robot/issues/200 -->
    <!-- <collision>
        <origin xyz="0 0 0" rpy="0 0 0" />
        <geometry>
          <box size="0.02 0.044 0.021"/>
        </geometry>
      </collision> -->
  </link>
  <!-- Gazebo sensor plugin -->
  <gazebo reference="sonar_0">
    <sensor name="sonar_0_sensor" type="ray">
      <visualize>false</visualize>
      <update_rate>5</update_rate>
      <ray>
        <scan>
          <horizontal>
            <samples>5</samples>
            <resolution>1.0</resolution>
            <min_angle>-0.24</min_angle>
            <max_angle>0.24</max_angle>
          </horizontal>
          <vertical>
            <samples>5</samples>
            <resolution>1.0</resolution>
            <min_angle>-0.05</min_angle>
            <max_angle>0.05</max_angle>
          </vertical>
        </scan>
        <range>
          <min>0.02</min>
          <max>4.0</max>
          <resolution>0.01</resolution>
        </range>
      </ray>
      <!-- Gazebo-ROS interface plugin -->
      <plugin filename="libgazebo_ros_range.so" name="gazebo_ros_range">
        <gaussianNoise>0.015</gaussianNoise>
        <alwaysOn>true</alwaysOn>
        <updateRate>5</updateRate>
        <topicName>/pi_sonar/sonar_0</topicName>
        <frameName>sonar_0</frameName>
        <fov>0.5</fov>
        <radiation>ultrasound</radiation>
      </plugin>
    </sensor>
  </gazebo>
  <joint name="sonar_1_joint" type="fixed">
    <parent link="base_link"/>
    <child link="sonar_1"/>
    <origin rpy="0 0 0.785" xyz="0.08 -0.07 0.15"/>
  </joint>
  <link name="sonar_1">
    <visual>
      <origin rpy="1.5707963267948966 0 1.5707963267948966" xyz="-0.006 0 0"/>
      <geometry>
        <mesh filename="package://magni_description/meshes/sensors/sonar_hc-sr04.dae"/>
      </geometry>
    </visual>
    <!-- removing colisions from sonars solves issue https://github.com/UbiquityRobotics/magni_robot/issues/200 -->
    <!-- <collision>
        <origin xyz="0 0 0" rpy="0 0 0" />
        <geometry>
          <box size="0.02 0.044 0.021"/>
        </geometry>
      </collision> -->
  </link>
  <!-- Gazebo sensor plugin -->
  <gazebo reference="sonar_1">
    <sensor name="sonar_1_sensor" type="ray">
      <visualize>false</visualize>
      <update_rate>5</update_rate>
      <ray>
        <scan>
          <horizontal>
            <samples>5</samples>
            <resolution>1.0</resolution>
            <min_angle>-0.24</min_angle>
            <max_angle>0.24</max_angle>
          </horizontal>
          <vertical>
            <samples>5</samples>
            <resolution>1.0</resolution>
            <min_angle>-0.05</min_angle>
            <max_angle>0.05</max_angle>
          </vertical>
        </scan>
        <range>
          <min>0.02</min>
          <max>4.0</max>
          <resolution>0.01</resolution>
        </range>
      </ray>
      <!-- Gazebo-ROS interface plugin -->
      <plugin filename="libgazebo_ros_range.so" name="gazebo_ros_range">
        <gaussianNoise>0.015</gaussianNoise>
        <alwaysOn>true</alwaysOn>
        <updateRate>5</updateRate>
        <topicName>/pi_sonar/sonar_1</topicName>
        <frameName>sonar_1</frameName>
        <fov>0.5</fov>
        <radiation>ultrasound</radiation>
      </plugin>
    </sensor>
  </gazebo>
  <joint name="sonar_2_joint" type="fixed">
    <parent link="base_link"/>
    <child link="sonar_2"/>
    <origin rpy="0 0 -0.785" xyz="0.08 -0.01 0.15"/>
  </joint>
  <link name="sonar_2">
    <visual>
      <origin rpy="1.5707963267948966 0 1.5707963267948966" xyz="-0.006 0 0"/>
      <geometry>
        <mesh filename="package://magni_description/meshes/sensors/sonar_hc-sr04.dae"/>
      </geometry>
    </visual>
    <!-- removing colisions from sonars solves issue https://github.com/UbiquityRobotics/magni_robot/issues/200 -->
    <!-- <collision>
        <origin xyz="0 0 0" rpy="0 0 0" />
        <geometry>
          <box size="0.02 0.044 0.021"/>
        </geometry>
      </collision> -->
  </link>
  <!-- Gazebo sensor plugin -->
  <gazebo reference="sonar_2">
    <sensor name="sonar_2_sensor" type="ray">
      <visualize>false</visualize>
      <update_rate>5</update_rate>
      <ray>
        <scan>
          <horizontal>
            <samples>5</samples>
            <resolution>1.0</resolution>
            <min_angle>-0.24</min_angle>
            <max_angle>0.24</max_angle>
          </horizontal>
          <vertical>
            <samples>5</samples>
            <resolution>1.0</resolution>
            <min_angle>-0.05</min_angle>
            <max_angle>0.05</max_angle>
          </vertical>
        </scan>
        <range>
          <min>0.02</min>
          <max>4.0</max>
          <resolution>0.01</resolution>
        </range>
      </ray>
      <!-- Gazebo-ROS interface plugin -->
      <plugin filename="libgazebo_ros_range.so" name="gazebo_ros_range">
        <gaussianNoise>0.015</gaussianNoise>
        <alwaysOn>true</alwaysOn>
        <updateRate>5</updateRate>
        <topicName>/pi_sonar/sonar_2</topicName>
        <frameName>sonar_2</frameName>
        <fov>0.5</fov>
        <radiation>ultrasound</radiation>
      </plugin>
    </sensor>
  </gazebo>
  <joint name="sonar_3_joint" type="fixed">
    <parent link="base_link"/>
    <child link="sonar_3"/>
    <origin rpy="0 0 0" xyz="0.08 0.04 0.15"/>
  </joint>
  <link name="sonar_3">
    <visual>
      <origin rpy="1.5707963267948966 0 1.5707963267948966" xyz="-0.006 0 0"/>
      <geometry>
        <mesh filename="package://magni_description/meshes/sensors/sonar_hc-sr04.dae"/>
      </geometry>
    </visual>
    <!-- removing colisions from sonars solves issue https://github.com/UbiquityRobotics/magni_robot/issues/200 -->
    <!-- <collision>
        <origin xyz="0 0 0" rpy="0 0 0" />
        <geometry>
          <box size="0.02 0.044 0.021"/>
        </geometry>
      </collision> -->
  </link>
  <!-- Gazebo sensor plugin -->
  <gazebo reference="sonar_3">
    <sensor name="sonar_3_sensor" type="ray">
      <visualize>false</visualize>
      <update_rate>5</update_rate>
      <ray>
        <scan>
          <horizontal>
            <samples>5</samples>
            <resolution>1.0</resolution>
            <min_angle>-0.24</min_angle>
            <max_angle>0.24</max_angle>
          </horizontal>
          <vertical>
            <samples>5</samples>
            <resolution>1.0</resolution>
            <min_angle>-0.05</min_angle>
            <max_angle>0.05</max_angle>
          </vertical>
        </scan>
        <range>
          <min>0.02</min>
          <max>4.0</max>
          <resolution>0.01</resolution>
        </range>
      </ray>
      <!-- Gazebo-ROS interface plugin -->
      <plugin filename="libgazebo_ros_range.so" name="gazebo_ros_range">
        <gaussianNoise>0.015</gaussianNoise>
        <alwaysOn>true</alwaysOn>
        <updateRate>5</updateRate>
        <topicName>/pi_sonar/sonar_3</topicName>
        <frameName>sonar_3</frameName>
        <fov>0.5</fov>
        <radiation>ultrasound</radiation>
      </plugin>
    </sensor>
  </gazebo>
  <joint name="sonar_4_joint" type="fixed">
    <parent link="base_link"/>
    <child link="sonar_4"/>
    <origin rpy="0 0 1.5707963267948966" xyz="0.01 0.14 0.15"/>
  </joint>
  <link name="sonar_4">
    <visual>
      <origin rpy="1.5707963267948966 0 1.5707963267948966" xyz="-0.006 0 0"/>
      <geometry>
        <mesh filename="package://magni_description/meshes/sensors/sonar_hc-sr04.dae"/>
      </geometry>
    </visual>
    <!-- removing colisions from sonars solves issue https://github.com/UbiquityRobotics/magni_robot/issues/200 -->
    <!-- <collision>
        <origin xyz="0 0 0" rpy="0 0 0" />
        <geometry>
          <box size="0.02 0.044 0.021"/>
        </geometry>
      </collision> -->
  </link>
  <!-- Gazebo sensor plugin -->
  <gazebo reference="sonar_4">
    <sensor name="sonar_4_sensor" type="ray">
      <visualize>false</visualize>
      <update_rate>5</update_rate>
      <ray>
        <scan>
          <horizontal>
            <samples>5</samples>
            <resolution>1.0</resolution>
            <min_angle>-0.24</min_angle>
            <max_angle>0.24</max_angle>
          </horizontal>
          <vertical>
            <samples>5</samples>
            <resolution>1.0</resolution>
            <min_angle>-0.05</min_angle>
            <max_angle>0.05</max_angle>
          </vertical>
        </scan>
        <range>
          <min>0.02</min>
          <max>4.0</max>
          <resolution>0.01</resolution>
        </range>
      </ray>
      <!-- Gazebo-ROS interface plugin -->
      <plugin filename="libgazebo_ros_range.so" name="gazebo_ros_range">
        <gaussianNoise>0.015</gaussianNoise>
        <alwaysOn>true</alwaysOn>
        <updateRate>5</updateRate>
        <topicName>/pi_sonar/sonar_4</topicName>
        <frameName>sonar_4</frameName>
        <fov>0.5</fov>
        <radiation>ultrasound</radiation>
      </plugin>
    </sensor>
  </gazebo>
</robot>

